<?xml version="1.0" encoding="utf-8"?>
<!-- =================================================================================== -->
<!-- |    This document was autogenerated by xacro from magician.urdf.xacro            | -->
<!-- |    EDITING THIS FILE BY HAND IS NOT RECOMMENDED                                 | -->
<!-- =================================================================================== -->
<!-- This URDF was automatically created by SolidWorks to URDF Exporter! Originally created by Stephen Brawner (brawner@gmail.com) 
     Commit Version: 1.5.0-0-g9aa0fdb  Build Version: 1.5.7004.21443
     For more information, please see http://wiki.ros.org/sw_urdf_exporter -->
<robot name="magician">
  <!-- ros_control plugin -->
  <gazebo>
    <plugin filename="libgazebo_ros_control.so" name="gazebo_ros_control">
      <robotSimType>gazebo_ros_control/DefaultRobotHWSim</robotSimType>
      <legacyModeNS>true</legacyModeNS>
    </plugin>
  </gazebo>
  <!-- mimicjoints -->
  <gazebo>
    <plugin filename="libroboticsgroup_gazebo_mimic_joint_plugin.so" name="mimic_plugin1">
      <joint>magician_joint2</joint>
      <mimicJoint>magician_fake_joint1</mimicJoint>
      <multiplier>-1.0</multiplier>
    </plugin>
  </gazebo>
  <gazebo>
    <plugin filename="libroboticsgroup_gazebo_mimic_joint_plugin.so" name="mimic_plugin2">
      <joint>magician_joint3</joint>
      <mimicJoint>magician_fake_joint2</mimicJoint>
      <multiplier>-1.0</multiplier>
    </plugin>
  </gazebo>
  <!-- visual -->
  <gazebo reference="magician_base_surface">
    <visual name="visual">
      <material>
        <script>
          <uri>file://media/materials/scripts/gazebo.material</uri>
          <name>Gazebo/Grey</name>
        </script>
      </material>
    </visual>
  </gazebo>
  <gazebo reference="magician_servos">
    <visual name="visual">
      <material>
        <script>
          <uri>file://media/materials/scripts/gazebo.material</uri>
          <name>Gazebo/Grey</name>
        </script>
      </material>
    </visual>
  </gazebo>
  <gazebo reference="magician_link2">
    <visual name="visual">
      <material>
        <script>
          <uri>file://media/materials/scripts/gazebo.material</uri>
          <name>Gazebo/Grey</name>
        </script>
      </material>
    </visual>
  </gazebo>
  <gazebo reference="magician_link2_surface">
    <visual name="visual">
      <material>
        <script>
          <uri>file://media/materials/scripts/gazebo.material</uri>
          <name>Gazebo/Grey</name>
        </script>
      </material>
    </visual>
  </gazebo>
  <gazebo reference="magician_link3">
    <visual name="visual">
      <material>
        <script>
          <uri>file://media/materials/scripts/gazebo.material</uri>
          <name>Gazebo/Grey</name>
        </script>
      </material>
    </visual>
  </gazebo>
  <gazebo reference="magician_link3_surface">
    <visual name="visual">
      <material>
        <script>
          <uri>file://media/materials/scripts/gazebo.material</uri>
          <name>Gazebo/Grey</name>
        </script>
      </material>
    </visual>
  </gazebo>
  <gazebo reference="magician_link4">
    <visual name="visual">
      <material>
        <script>
          <uri>file://media/materials/scripts/gazebo.material</uri>
          <name>Gazebo/Grey</name>
        </script>
      </material>
    </visual>
  </gazebo>
  <link name="base_link">
    <inertial>
      <origin rpy="0 0 0" xyz="-0.00019215 -0.10884 0.23391"/>
      <mass value="26.051"/>
      <inertia ixx="0.52558" ixy="-0.00076155" ixz="0.00076702" iyy="1.5311" iyz="0.016651" izz="1.1217"/>
    </inertial>
    <visual>
      <origin rpy="0 0 0" xyz="0 0 0"/>
      <geometry>
        <mesh filename="package://magician_description/meshes/base_link.STL"/>
      </geometry>
      <material name="">
        <color rgba="0.52941 0.54902 0.54902 1"/>
      </material>
    </visual>
    <collision>
      <origin rpy="0 0 0" xyz="0 0 0"/>
      <geometry>
        <mesh filename="package://magician_description/meshes/base_link.STL"/>
      </geometry>
    </collision>
  </link>
  <link name="camera1">
    <inertial>
      <origin rpy="0 0 0" xyz="-0.0125 0.006 -2.7756E-17"/>
      <mass value="0.02"/>
      <inertia ixx="2.7483E-06" ixy="-5.6469E-23" ixz="4.5613E-23" iyy="2.0833E-06" iyz="2.9848E-23" izz="2.7483E-06"/>
    </inertial>
    <visual>
      <origin rpy="0 0 0" xyz="0 0 0"/>
      <geometry>
        <mesh filename="package://magician_description/meshes/camera1.STL"/>
      </geometry>
      <material name="">
        <color rgba="0.79608 0.82353 0.93725 1"/>
      </material>
    </visual>
    <collision>
      <origin rpy="0 0 0" xyz="0 0 0"/>
      <geometry>
        <mesh filename="package://magician_description/meshes/camera1.STL"/>
      </geometry>
    </collision>
  </link>
  <joint name="camera1" type="fixed">
    <origin rpy="0 0 0" xyz="-0.215 0.582 0.1115"/>
    <parent link="base_link"/>
    <child link="camera1"/>
    <axis xyz="0 0 0"/>
  </joint>
  <link name="camera2">
    <inertial>
      <origin rpy="0 0 0" xyz="0.0125 0.006 0"/>
      <mass value="0.02"/>
      <inertia ixx="2.7483E-06" ixy="-1.7546E-23" ixz="-8.267E-23" iyy="2.0833E-06" iyz="3.5827E-22" izz="2.7483E-06"/>
    </inertial>
    <visual>
      <origin rpy="0 0 0" xyz="0 0 0"/>
      <geometry>
        <mesh filename="package://magician_description/meshes/camera2.STL"/>
      </geometry>
      <material name="">
        <color rgba="0.79608 0.82353 0.93725 1"/>
      </material>
    </visual>
    <collision>
      <origin rpy="0 0 0" xyz="0 0 0"/>
      <geometry>
        <mesh filename="package://magician_description/meshes/camera2.STL"/>
      </geometry>
    </collision>
  </link>
  <joint name="camera2" type="fixed">
    <origin rpy="0 0 0" xyz="0.233 0.582 0.1115 "/>
    <parent link="base_link"/>
    <child link="camera2"/>
    <axis xyz="0 0 0"/>
  </joint>
  <transmission name="magician_joint1_trans">
    <type>transmission_interface/SimpleTransmission</type>
    <joint name="magician_joint1">
      <hardwareInterface>hardware_interface/PositionJointInterface</hardwareInterface>
    </joint>
    <actuator name="magician_joint1_motor">
      <mechanicalReduction>1</mechanicalReduction>
    </actuator>
  </transmission>
  <transmission name="magician_joint2_trans">
    <type>transmission_interface/SimpleTransmission</type>
    <joint name="magician_joint2">
      <hardwareInterface>hardware_interface/PositionJointInterface</hardwareInterface>
    </joint>
    <actuator name="magician_joint2_motor">
      <mechanicalReduction>1</mechanicalReduction>
    </actuator>
  </transmission>
  <transmission name="magician_fake_joint1">
    <type>transmission_interface/SimpleTransmission</type>
    <joint name="magician_fake_joint1">
      <hardwareInterface>hardware_interface/PositionJointInterface</hardwareInterface>
    </joint>
    <actuator name="magician_fake_joint1_motor">
      <mechanicalReduction>1</mechanicalReduction>
    </actuator>
  </transmission>
  <transmission name="magician_joint3_trans">
    <type>transmission_interface/SimpleTransmission</type>
    <joint name="magician_joint3">
      <hardwareInterface>hardware_interface/PositionJointInterface</hardwareInterface>
    </joint>
    <actuator name="magician_joint3_motor">
      <mechanicalReduction>1</mechanicalReduction>
    </actuator>
  </transmission>
  <transmission name="magician_fake_joint2">
    <type>transmission_interface/SimpleTransmission</type>
    <joint name="magician_fake_joint2">
      <hardwareInterface>hardware_interface/PositionJointInterface</hardwareInterface>
    </joint>
    <actuator name="magician_fake_joint2_motor">
      <mechanicalReduction>1</mechanicalReduction>
    </actuator>
  </transmission>
  <link name="world"/>
  <joint name="world_joint" type="fixed">
    <origin rpy="0 0 0" xyz="0 0 0"/>
    <parent link="world"/>
    <child link="base_link"/>
    <axis xyz="0 0 0"/>
  </joint>
  <link name="magician_origin"/>
  <joint name="magician_frame_joint" type="fixed">
    <origin rpy="0 0 0" xyz="0 0 0.262"/>
    <parent link="base_link"/>
    <child link="magician_origin"/>
    <axis xyz="0 0 0"/>
  </joint>
  <link name="magician_base">
    <inertial>
      <origin rpy="0 0 0" xyz="-0.00035432 -0.00080566 0.023187"/>
      <mass value="0.23009"/>
      <inertia ixx="0.00065784" ixy="-4.8312E-06" ixz="1.2493E-06" iyy="0.00069673" iyz="4.3823E-07" izz="0.0012945"/>
    </inertial>
    <visual>
      <origin rpy="0 0 0" xyz="0 0 0"/>
      <geometry>
        <mesh filename="package://magician_description/meshes/magician_base.STL"/>
      </geometry>
      <material name="">
        <color rgba="1 1 1 1"/>
      </material>
    </visual>
    <collision>
      <origin rpy="0 0 0" xyz="0 0 0"/>
      <geometry>
        <mesh filename="package://magician_description/meshes/magician_base.STL"/>
      </geometry>
    </collision>
  </link>
  <joint name="magician_origin_joint1" type="fixed">
    <origin rpy="0 0 0" xyz="0 0 -0.139"/>
    <parent link="magician_origin"/>
    <child link="magician_base"/>
    <axis xyz="0 0 0"/>
  </joint>
  <link name="magician_link1">
    <inertial>
      <origin rpy="0 0 0" xyz="0.00024809 -0.00074864 0.040762"/>
      <mass value="0.081469"/>
      <inertia ixx="0.00020859" ixy="8.163E-08" ixz="4.6298E-07" iyy="9.5838E-05" iyz="3.2246E-06" izz="0.00015246"/>
    </inertial>
    <visual>
      <origin rpy="0 0 0" xyz="0 0 0"/>
      <geometry>
        <mesh filename="package://magician_description/meshes/magician_link1.STL"/>
      </geometry>
      <material name="">
        <color rgba="1 1 1 1"/>
      </material>
    </visual>
    <collision>
      <origin rpy="0 0 0" xyz="0 0 0"/>
      <geometry>
        <mesh filename="package://magician_description/meshes/magician_link1.STL"/>
      </geometry>
    </collision>
  </link>
  <joint name="magician_joint1" type="revolute">
    <origin rpy="0 0 0" xyz="0 0 0.0569"/>
    <parent link="magician_base"/>
    <child link="magician_link1"/>
    <axis xyz="0 0 1"/>
    <limit effort="6" lower="-2.1816" upper="2.1816" velocity="1.57"/>
  </joint>
  <link name="magician_link2">
    <inertial>
      <origin rpy="0 0 0" xyz="-0.076276 0.029436 2.1815E-06"/>
      <mass value="0.047726"/>
      <inertia ixx="3.5818E-05" ixy="-4.4023E-06" ixz="-7.1903E-09" iyy="0.00014556" iyz="2.3353E-09" izz="0.00015167"/>
    </inertial>
    <visual>
      <origin rpy="0 0 0" xyz="0 0 0"/>
      <geometry>
        <mesh filename="package://magician_description/meshes/magician_link2.STL"/>
      </geometry>
      <material name="">
        <color rgba="0.501960784313725 0.501960784313725 0.501960784313725 1"/>
      </material>
    </visual>
    <collision>
      <origin rpy="0 0 0" xyz="0 0 0"/>
      <geometry>
        <mesh filename="package://magician_description/meshes/magician_link2.STL"/>
      </geometry>
    </collision>
  </link>
  <joint name="magician_joint2" type="revolute">
    <origin rpy="0 1.5707963267948966 0" xyz="0 0 0.0821"/>
    <parent link="magician_link1"/>
    <child link="magician_link2"/>
    <axis xyz="0 0 1"/>
    <limit effort="6" lower="0.35" upper="1.57" velocity="1.57"/>
  </joint>
  <link name="magician_link3">
    <inertial>
      <origin rpy="0 0 0" xyz="0.029209 -0.054163 -8.4342E-05"/>
      <mass value="0.042983"/>
      <inertia ixx="0.00013733" ixy="-9.7605E-08" ixz="-1.1091E-07" iyy="2.3432E-05" iyz="3.5599E-07" izz="0.00014558"/>
    </inertial>
    <visual>
      <origin rpy="0 0 0" xyz="0 0 0"/>
      <geometry>
        <mesh filename="package://magician_description/meshes/magician_link3.STL"/>
      </geometry>
      <material name="">
        <color rgba="0.501960784313725 0.501960784313725 0.501960784313725 1"/>
      </material>
    </visual>
    <collision>
      <origin rpy="0 0 0" xyz="0 0 0"/>
      <geometry>
        <mesh filename="package://magician_description/meshes/magician_link3.STL"/>
      </geometry>
    </collision>
  </link>
  <joint name="magician_fake_joint1" type="revolute">
    <origin rpy="-3.1415926535897932 0 -3.1415926535897932" xyz="-0.135 0 0"/>
    <parent link="magician_link2"/>
    <child link="magician_fake_link"/>
    <axis xyz="0 0 -1"/>
    <limit effort="6" lower="-1.57" upper="-0.35" velocity="1.57"/>
    <mimic joint="magician_joint2" multiplier="-1" offset="0"/>
  </joint>
  <link name="magician_fake_link">
    <inertial>
      <origin rpy="0 0 0" xyz="0 0 0"/>
      <mass value="0.025"/>
      <inertia ixx="2.5E-4" ixy="0" ixz="0" iyy="2.5E-4" iyz="0" izz="2.5E-4"/>
    </inertial>
  </link>
  <joint name="magician_joint3" type="revolute">
    <origin rpy="0 0 0" xyz="0 0 0"/>
    <parent link="magician_fake_link"/>
    <child link="magician_link3"/>
    <axis xyz="0 0 -1"/>
    <limit effort="6" lower="0.62" upper="1.57" velocity="1.57"/>
  </joint>
  <link name="magician_link4">
    <inertial>
      <origin rpy="0 0 0" xyz="-0.019694 0.0034659 0.0001155"/>
      <mass value="0.020564"/>
      <inertia ixx="3.7203E-06" ixy="7.6009E-07" ixz="3.146E-08" iyy="4.5639E-06" iyz="-5.7432E-08" izz="6.427E-06"/>
    </inertial>
    <visual>
      <origin rpy="0 0 0" xyz="0 0 0"/>
      <geometry>
        <mesh filename="package://magician_description/meshes/magician_link4.STL"/>
      </geometry>
      <material name="">
        <color rgba="0.501960784313725 0.501960784313725 0.501960784313725 1"/>
      </material>
    </visual>
    <collision>
      <origin rpy="0 0 0" xyz="0 0 0"/>
      <geometry>
        <mesh filename="package://magician_description/meshes/magician_link4.STL"/>
      </geometry>
    </collision>
  </link>
  <joint name="magician_fake_joint2" type="revolute">
    <origin rpy="3.1415926535897932 0 1.5707963267948966" xyz="0 -0.147 0"/>
    <parent link="magician_link3"/>
    <child link="magician_link4"/>
    <axis xyz="0 0 1"/>
    <limit effort="6" lower="-1.57" upper="-0.62" velocity="1.57"/>
    <mimic joint="magician_joint3" multiplier="-1" offset="0"/>
  </joint>
  <link name="magician_arm_end"/>
  <joint name="magician_link4_joint1" type="fixed">
    <origin rpy="-1.5707963267948966 3.1415926535897932 0" xyz="0 0 0"/>
    <parent link="magician_link4"/>
    <child link="magician_arm_end"/>
  </joint>
  <link name="magician_link3_surface">
    <inertial>
      <origin rpy="0 0 0" xyz="0.059385 -0.050176 -2.6308E-06"/>
      <mass value="0.015005"/>
      <inertia ixx="1.8842E-05" ixy="-3.9211E-07" ixz="4.9615E-10" iyy="3.6097E-06" iyz="-1.2797E-09" izz="1.6901E-05"/>
    </inertial>
    <visual>
      <origin rpy="0 0 0" xyz="0 0 0"/>
      <geometry>
        <mesh filename="package://magician_description/meshes/magician_link3_surface.STL"/>
      </geometry>
      <material name="">
        <color rgba="0.501960784313725 0.501960784313725 0.501960784313725 1"/>
      </material>
    </visual>
    <collision>
      <origin rpy="0 0 0" xyz="0 0 0"/>
      <geometry>
        <mesh filename="package://magician_description/meshes/magician_link3_surface.STL"/>
      </geometry>
    </collision>
  </link>
  <joint name="magician_link3_joint1" type="fixed">
    <origin rpy="0 0 0" xyz="0 0 0"/>
    <parent link="magician_link3"/>
    <child link="magician_link3_surface"/>
    <axis xyz="0 0 0"/>
  </joint>
  <link name="magician_link2_surface">
    <inertial>
      <origin rpy="0 0 0" xyz="-0.066726 0.060698 5.5359E-07"/>
      <mass value="0.018846"/>
      <inertia ixx="5.9574E-06" ixy="-5.1053E-08" ixz="3.3782E-09" iyy="2.8034E-05" iyz="-1.6336E-11" izz="2.3816E-05"/>
    </inertial>
    <visual>
      <origin rpy="0 0 0" xyz="0 0 0"/>
      <geometry>
        <mesh filename="package://magician_description/meshes/magician_link2_surface.STL"/>
      </geometry>
      <material name="">
        <color rgba="0.501960784313725 0.501960784313725 0.501960784313725 1"/>
      </material>
    </visual>
    <collision>
      <origin rpy="0 0 0" xyz="0 0 0"/>
      <geometry>
        <mesh filename="package://magician_description/meshes/magician_link2_surface.STL"/>
      </geometry>
    </collision>
  </link>
  <joint name="magician_link2_joint1" type="fixed">
    <origin rpy="0 0 0" xyz="0 0 0"/>
    <parent link="magician_link2"/>
    <child link="magician_link2_surface"/>
    <axis xyz="0 0 0"/>
  </joint>
  <link name="magician_servos">
    <inertial>
      <origin rpy="0 0 0" xyz="-3.3282E-06 0 0.0821"/>
      <mass value="0.21777"/>
      <inertia ixx="5.4372E-05" ixy="-1.467E-18" ixz="-1.6192E-19" iyy="0.00011754" iyz="7.4188E-21" izz="0.00011754"/>
    </inertial>
    <visual>
      <origin rpy="0 0 0" xyz="0 0 0"/>
      <geometry>
        <mesh filename="package://magician_description/meshes/magician_servos.STL"/>
      </geometry>
      <material name="">
        <color rgba="0.501960784313725 0.501960784313725 0.501960784313725 1"/>
      </material>
    </visual>
    <collision>
      <origin rpy="0 0 0" xyz="0 0 0"/>
      <geometry>
        <mesh filename="package://magician_description/meshes/magician_servos.STL"/>
      </geometry>
    </collision>
  </link>
  <joint name="magician_link1_joint1" type="fixed">
    <origin rpy="0 0 0" xyz="0 0 0"/>
    <parent link="magician_link1"/>
    <child link="magician_servos"/>
    <axis xyz="0 0 0"/>
  </joint>
  <link name="magician_base_surface">
    <inertial>
      <origin rpy="0 0 0" xyz="0 0 0"/>
      <mass value="0"/>
      <inertia ixx="0" ixy="0" ixz="0" iyy="0" iyz="0" izz="0"/>
    </inertial>
    <visual>
      <origin rpy="0 0 0" xyz="0 0 0"/>
      <geometry>
        <mesh filename="package://magician_description/meshes/magician_base_surface.STL"/>
      </geometry>
      <material name="">
        <color rgba="0.501960784313725 0.501960784313725 0.501960784313725 1"/>
      </material>
    </visual>
    <collision>
      <origin rpy="0 0 0" xyz="0 0 0"/>
      <geometry>
        <mesh filename="package://magician_description/meshes/magician_base_surface.STL"/>
      </geometry>
    </collision>
  </link>
  <joint name="magician_base_joint1" type="fixed">
    <origin rpy="0 0 0" xyz="0 0 0"/>
    <parent link="magician_base"/>
    <child link="magician_base_surface"/>
    <axis xyz="0 0 0"/>
  </joint>
  <link name="magician_end_turnplate"/>
  <joint name="magician_fake_joint3" type="revolute">
    <origin rpy="0 0 0" xyz="0 0 0"/>
    <parent link="magician_arm_end"/>
    <child link="magician_end_turnplate"/>
    <axis xyz="0 0 1"/>
    <limit effort="6" lower="-2.1816" upper="2.1816" velocity="1.57"/>
    <mimic joint="magician_joint1" multiplier="-1" offset="0"/>
  </joint>
  <link name="magician_end_link"/>
  <joint name="magician_end_turnplate_joint1" type="fixed">
    <origin rpy="0 0 0" xyz="0 0 0"/>
    <parent link="magician_end_turnplate"/>
    <child link="magician_end_link"/>
    <axis xyz="0 0 0"/>
  </joint>
  <link name="magician_end_effctor"/>
  <joint name="magician_end_link_joint1" type="fixed">
    <origin rpy="0 0 0" xyz="0 0 0"/>
    <parent link="magician_end_link"/>
    <child link="magician_end_effctor"/>
    <axis xyz="0 0 0"/>
  </joint>
</robot>

